<?xml version="1.0"?>
<sdf version="1.8">
  <model name="mit_cheetah">
    <pose>0 0 0.35 0 0 0</pose>
    
    <link name="base_link">
      <inertial>
        <mass>10</mass>
        <inertia>
          <ixx>0.1</ixx><ixy>0</ixy><ixz>0</ixz>
          <iyy>0.5</iyy><iyz>0</iyz>
          <izz>0.5</izz>
        </inertia>
      </inertial>
      <visual name="body">
        <geometry>
          <box><size>0.4 0.2 0.1</size></box>
        </geometry>
        <material>
          <ambient>0.3 0.3 0.3 1</ambient>
          <diffuse>0.3 0.3 0.3 1</diffuse>
        </material>
      </visual>
      <collision name="body_collision">
        <geometry>
          <box><size>0.4 0.2 0.1</size></box>
        </geometry>
      </collision>
    </link>

    <!-- Front Right Leg -->
    <link name="fr_thigh">
      <pose>0.15 -0.1 -0.05 0 0 0</pose>
      <inertial>
        <mass>0.5</mass>
        <inertia>
          <ixx>0.001</ixx><ixy>0</ixy><ixz>0</ixz>
          <iyy>0.001</iyy><iyz>0</iyz>
          <izz>0.0005</izz>
        </inertia>
      </inertial>
      <visual name="thigh">
        <pose>0 0 -0.075 0 0 0</pose>
        <geometry>
          <cylinder><radius>0.02</radius><length>0.15</length></cylinder>
        </geometry>
        <material>
          <ambient>0.8 0.2 0.2 1</ambient>
          <diffuse>0.8 0.2 0.2 1</diffuse>
        </material>
      </visual>
      <collision name="thigh_collision">
        <pose>0 0 -0.075 0 0 0</pose>
        <geometry>
          <cylinder><radius>0.02</radius><length>0.15</length></cylinder>
        </geometry>
      </collision>
    </link>

    <link name="fr_shin">
      <pose>0.15 -0.1 -0.2 0 0 0</pose>
      <inertial>
        <mass>0.3</mass>
        <inertia>
          <ixx>0.001</ixx><ixy>0</ixy><ixz>0</ixz>
          <iyy>0.001</iyy><iyz>0</iyz>
          <izz>0.0003</izz>
        </inertia>
      </inertial>
      <visual name="shin">
        <pose>0 0 -0.075 0 0 0</pose>
        <geometry>
          <cylinder><radius>0.015</radius><length>0.15</length></cylinder>
        </geometry>
        <material>
          <ambient>0.6 0.1 0.1 1</ambient>
          <diffuse>0.6 0.1 0.1 1</diffuse>
        </material>
      </visual>
      <collision name="shin_collision">
        <pose>0 0 -0.075 0 0 0</pose>
        <geometry>
          <cylinder><radius>0.015</radius><length>0.15</length></cylinder>
        </geometry>
      </collision>
      <collision name="foot">
        <pose>0 0 -0.15 0 0 0</pose>
        <geometry>
          <sphere><radius>0.025</radius></sphere>
        </geometry>
        <surface>
          <friction>
            <ode>
              <mu>1.0</mu>
              <mu2>1.0</mu2>
            </ode>
          </friction>
        </surface>
      </collision>
    </link>

    <!-- Front Left Leg -->
    <link name="fl_thigh">
      <pose>0.15 0.1 -0.05 0 0 0</pose>
      <inertial>
        <mass>0.5</mass>
        <inertia>
          <ixx>0.001</ixx><ixy>0</ixy><ixz>0</ixz>
          <iyy>0.001</iyy><iyz>0</iyz>
          <izz>0.0005</izz>
        </inertia>
      </inertial>
      <visual name="thigh">
        <pose>0 0 -0.075 0 0 0</pose>
        <geometry>
          <cylinder><radius>0.02</radius><length>0.15</length></cylinder>
        </geometry>
        <material>
          <ambient>0.8 0.2 0.2 1</ambient>
          <diffuse>0.8 0.2 0.2 1</diffuse>
        </material>
      </visual>
      <collision name="thigh_collision">
        <pose>0 0 -0.075 0 0 0</pose>
        <geometry>
          <cylinder><radius>0.02</radius><length>0.15</length></cylinder>
        </geometry>
      </collision>
    </link>

    <link name="fl_shin">
      <pose>0.15 0.1 -0.2 0 0 0</pose>
      <inertial>
        <mass>0.3</mass>
        <inertia>
          <ixx>0.001</ixx><ixy>0</ixy><ixz>0</ixz>
          <iyy>0.001</iyy><iyz>0</iyz>
          <izz>0.0003</izz>
        </inertia>
      </inertial>
      <visual name="shin">
        <pose>0 0 -0.075 0 0 0</pose>
        <geometry>
          <cylinder><radius>0.015</radius><length>0.15</length></cylinder>
        </geometry>
        <material>
          <ambient>0.6 0.1 0.1 1</ambient>
          <diffuse>0.6 0.1 0.1 1</diffuse>
        </material>
      </visual>
      <collision name="shin_collision">
        <pose>0 0 -0.075 0 0 0</pose>
        <geometry>
          <cylinder><radius>0.015</radius><length>0.15</length></cylinder>
        </geometry>
      </collision>
      <collision name="foot">
        <pose>0 0 -0.15 0 0 0</pose>
        <geometry>
          <sphere><radius>0.025</radius></sphere>
        </geometry>
        <surface>
          <friction>
            <ode>
              <mu>1.0</mu>
              <mu2>1.0</mu2>
            </ode>
          </friction>
        </surface>
      </collision>
    </link>

    <!-- Rear Right Leg -->
    <link name="rr_thigh">
      <pose>-0.15 -0.1 -0.05 0 0 0</pose>
      <inertial>
        <mass>0.5</mass>
        <inertia>
          <ixx>0.001</ixx><ixy>0</ixy><ixz>0</ixz>
          <iyy>0.001</iyy><iyz>0</iyz>
          <izz>0.0005</izz>
        </inertia>
      </inertial>
      <visual name="thigh">
        <pose>0 0 -0.075 0 0 0</pose>
        <geometry>
          <cylinder><radius>0.02</radius><length>0.15</length></cylinder>
        </geometry>
        <material>
          <ambient>0.8 0.2 0.2 1</ambient>
          <diffuse>0.8 0.2 0.2 1</diffuse>
        </material>
      </visual>
      <collision name="thigh_collision">
        <pose>0 0 -0.075 0 0 0</pose>
        <geometry>
          <cylinder><radius>0.02</radius><length>0.15</length></cylinder>
        </geometry>
      </collision>
    </link>

    <link name="rr_shin">
      <pose>-0.15 -0.1 -0.2 0 0 0</pose>
      <inertial>
        <mass>0.3</mass>
        <inertia>
          <ixx>0.001</ixx><ixy>0</ixy><ixz>0</ixz>
          <iyy>0.001</iyy><iyz>0</iyz>
          <izz>0.0003</izz>
        </inertia>
      </inertial>
      <visual name="shin">
        <pose>0 0 -0.075 0 0 0</pose>
        <geometry>
          <cylinder><radius>0.015</radius><length>0.15</length></cylinder>
        </geometry>
        <material>
          <ambient>0.6 0.1 0.1 1</ambient>
          <diffuse>0.6 0.1 0.1 1</diffuse>
        </material>
      </visual>
      <collision name="shin_collision">
        <pose>0 0 -0.075 0 0 0</pose>
        <geometry>
          <cylinder><radius>0.015</radius><length>0.15</length></cylinder>
        </geometry>
      </collision>
      <collision name="foot">
        <pose>0 0 -0.15 0 0 0</pose>
        <geometry>
          <sphere><radius>0.025</radius></sphere>
        </geometry>
        <surface>
          <friction>
            <ode>
              <mu>1.0</mu>
              <mu2>1.0</mu2>
            </ode>
          </friction>
        </surface>
      </collision>
    </link>

    <!-- Rear Left Leg -->
    <link name="rl_thigh">
      <pose>-0.15 0.1 -0.05 0 0 0</pose>
      <inertial>
        <mass>0.5</mass>
        <inertia>
          <ixx>0.001</ixx><ixy>0</ixy><ixz>0</ixz>
          <iyy>0.001</iyy><iyz>0</iyz>
          <izz>0.0005</izz>
        </inertia>
      </inertial>
      <visual name="thigh">
        <pose>0 0 -0.075 0 0 0</pose>
        <geometry>
          <cylinder><radius>0.02</radius><length>0.15</length></cylinder>
        </geometry>
        <material>
          <ambient>0.8 0.2 0.2 1</ambient>
          <diffuse>0.8 0.2 0.2 1</diffuse>
        </material>
      </visual>
      <collision name="thigh_collision">
        <pose>0 0 -0.075 0 0 0</pose>
        <geometry>
          <cylinder><radius>0.02</radius><length>0.15</length></cylinder>
        </geometry>
      </collision>
    </link>

    <link name="rl_shin">
      <pose>-0.15 0.1 -0.2 0 0 0</pose>
      <inertial>
        <mass>0.3</mass>
        <inertia>
          <ixx>0.001</ixx><ixy>0</ixy><ixz>0</ixz>
          <iyy>0.001</iyy><iyz>0</iyz>
          <izz>0.0003</izz>
        </inertia>
      </inertial>
      <visual name="shin">
        <pose>0 0 -0.075 0 0 0</pose>
        <geometry>
          <cylinder><radius>0.015</radius><length>0.15</length></cylinder>
        </geometry>
        <material>
          <ambient>0.6 0.1 0.1 1</ambient>
          <diffuse>0.6 0.1 0.1 1</diffuse>
        </material>
      </visual>
      <collision name="shin_collision">
        <pose>0 0 -0.075 0 0 0</pose>
        <geometry>
          <cylinder><radius>0.015</radius><length>0.15</length></cylinder>
        </geometry>
      </collision>
      <collision name="foot">
        <pose>0 0 -0.15 0 0 0</pose>
        <geometry>
          <sphere><radius>0.025</radius></sphere>
        </geometry>
        <surface>
          <friction>
            <ode>
              <mu>1.0</mu>
              <mu2>1.0</mu2>
            </ode>
          </friction>
        </surface>
      </collision>
    </link>

    <!-- Hip Joints -->
    <joint name="fr_hip" type="revolute">
      <parent>base_link</parent>
      <child>fr_thigh</child>
      <axis><xyz>0 1 0</xyz><limit><lower>-1.0</lower><upper>1.0</upper></limit></axis>
    </joint>

    <joint name="fl_hip" type="revolute">
      <parent>base_link</parent>
      <child>fl_thigh</child>
      <axis><xyz>0 1 0</xyz><limit><lower>-1.0</lower><upper>1.0</upper></limit></axis>
    </joint>

    <joint name="rr_hip" type="revolute">
      <parent>base_link</parent>
      <child>rr_thigh</child>
      <axis><xyz>0 1 0</xyz><limit><lower>-1.0</lower><upper>1.0</upper></limit></axis>
    </joint>

    <joint name="rl_hip" type="revolute">
      <parent>base_link</parent>
      <child>rl_thigh</child>
      <axis><xyz>0 1 0</xyz><limit><lower>-1.0</lower><upper>1.0</upper></limit></axis>
    </joint>

    <!-- Knee Joints -->
    <joint name="fr_knee" type="revolute">
      <parent>fr_thigh</parent>
      <child>fr_shin</child>
      <axis><xyz>0 1 0</xyz><limit><lower>-2.5</lower><upper>0</upper></limit></axis>
    </joint>

    <joint name="fl_knee" type="revolute">
      <parent>fl_thigh</parent>
      <child>fl_shin</child>
      <axis><xyz>0 1 0</xyz><limit><lower>-2.5</lower><upper>0</upper></limit></axis>
    </joint>

    <joint name="rr_knee" type="revolute">
      <parent>rr_thigh</parent>
      <child>rr_shin</child>
      <axis><xyz>0 1 0</xyz><limit><lower>-2.5</lower><upper>0</upper></limit></axis>
    </joint>

    <joint name="rl_knee" type="revolute">
      <parent>rl_thigh</parent>
      <child>rl_shin</child>
      <axis><xyz>0 1 0</xyz><limit><lower>-2.5</lower><upper>0</upper></limit></axis>
    </joint>

    <!-- Control Plugins -->
    <plugin filename="gz-sim-joint-state-publisher-system" name="gz::sim::systems::JointStatePublisher"/>
    
    <plugin filename="gz-sim-joint-position-controller-system" name="gz::sim::systems::JointPositionController">
      <joint_name>fr_hip</joint_name>
      <topic>/model/mit_cheetah/joint/fr_hip/cmd_pos</topic>
      <p_gain>200</p_gain>
      <i_gain>10</i_gain>
      <d_gain>20</d_gain>
    </plugin>
    <plugin filename="gz-sim-joint-position-controller-system" name="gz::sim::systems::JointPositionController">
      <joint_name>fr_knee</joint_name>
      <topic>/model/mit_cheetah/joint/fr_knee/cmd_pos</topic>
      <p_gain>200</p_gain>
      <i_gain>10</i_gain>
      <d_gain>20</d_gain>
    </plugin>

    <plugin filename="gz-sim-joint-position-controller-system" name="gz::sim::systems::JointPositionController">
      <joint_name>fl_hip</joint_name>
      <topic>/model/mit_cheetah/joint/fl_hip/cmd_pos</topic>
      <p_gain>200</p_gain>
      <i_gain>10</i_gain>
      <d_gain>20</d_gain>
    </plugin>
    <plugin filename="gz-sim-joint-position-controller-system" name="gz::sim::systems::JointPositionController">
      <joint_name>fl_knee</joint_name>
      <topic>/model/mit_cheetah/joint/fl_knee/cmd_pos</topic>
      <p_gain>200</p_gain>
      <i_gain>10</i_gain>
      <d_gain>20</d_gain>
    </plugin>

    <plugin filename="gz-sim-joint-position-controller-system" name="gz::sim::systems::JointPositionController">
      <joint_name>rr_hip</joint_name>
      <topic>/model/mit_cheetah/joint/rr_hip/cmd_pos</topic>
      <p_gain>200</p_gain>
      <i_gain>10</i_gain>
      <d_gain>20</d_gain>
    </plugin>
    <plugin filename="gz-sim-joint-position-controller-system" name="gz::sim::systems::JointPositionController">
      <joint_name>rr_knee</joint_name>
      <topic>/model/mit_cheetah/joint/rr_knee/cmd_pos</topic>
      <p_gain>200</p_gain>
      <i_gain>10</i_gain>
      <d_gain>20</d_gain>
    </plugin>

    <plugin filename="gz-sim-joint-position-controller-system" name="gz::sim::systems::JointPositionController">
      <joint_name>rl_hip</joint_name>
      <topic>/model/mit_cheetah/joint/rl_hip/cmd_pos</topic>
      <p_gain>200</p_gain>
      <i_gain>10</i_gain>
      <d_gain>20</d_gain>
    </plugin>
    <plugin filename="gz-sim-joint-position-controller-system" name="gz::sim::systems::JointPositionController">
      <joint_name>rl_knee</joint_name>
      <topic>/model/mit_cheetah/joint/rl_knee/cmd_pos</topic>
      <p_gain>200</p_gain>
      <i_gain>10</i_gain>
      <d_gain>20</d_gain>
    </plugin>

  </model>
</sdf>