<sdf version='1.11'>
  <model name='rrr_robot'>
  <self_collide>true</self_collide>
    <link name='base_link'>
      <inertial>
        <pose>0 0 0 0 0 0</pose>
        <mass>5</mass>
        <inertia>
          <ixx>0.050000000000000003</ixx>
          <ixy>0</ixy>
          <ixz>0</ixz>
          <iyy>0.050000000000000003</iyy>
          <iyz>0</iyz>
          <izz>0.050000000000000003</izz>
        </inertia>
      </inertial>
      <collision name='base_link_collision'>
        <pose>0 0 0 0 0 0</pose>
        <geometry>
          <cylinder>
            <length>0.050000000000000003</length>
            <radius>0.01</radius>
          </cylinder>
        </geometry>
      </collision>
      <visual name='base_link_visual'>
        <pose>0 0 0 0 0 0</pose>
        <geometry>
          <cylinder>
            <length>0.050000000000000003</length>
            <radius>0.01</radius>
          </cylinder>
        </geometry>
        <material>
          <diffuse>0.25 0.25 0.25 1</diffuse>
          <ambient>0.25 0.25 0.25 1</ambient>
        </material>
      </visual>
    </link>
    <joint name='joint0' type='revolute'>
      <pose relative_to='base_link'>0 0 0.050000000000000003 0 0 0</pose>
      <parent>base_link</parent>
      <child>link0</child>
      <axis>
        <xyz>0 0 1</xyz>
        <limit>
          <lower>-3.1400000000000001</lower>
          <upper>3.1400000000000001</upper>
          <effort>10</effort>
          <velocity>1</velocity>
        </limit>
        <dynamics>
          <spring_reference>0</spring_reference>
          <spring_stiffness>0</spring_stiffness>
        </dynamics>
      </axis>
    </joint>
    <link name='link0'>
      <pose relative_to='joint0'>0 0 0 0 0 0</pose>
      <inertial>
        <pose>0 0 0 0 0 0</pose>
        <mass>3</mass>
        <inertia>
          <ixx>0.029999999999999999</ixx>
          <ixy>0</ixy>
          <ixz>0</ixz>
          <iyy>0.029999999999999999</iyy>
          <iyz>0</iyz>
          <izz>0.029999999999999999</izz>
        </inertia>
      </inertial>
      <collision name='link0_collision'>
        <pose>0 0 0.01 0 0 0</pose>
        <geometry>
          <cylinder>
            <length>0.02</length>
            <radius>0.02</radius>
          </cylinder>
        </geometry>
      </collision>
      <visual name='link0_visual'>
        <pose>0 0 0.01 0 0 0</pose>
        <geometry>
          <cylinder>
            <length>0.02</length>
            <radius>0.02</radius>
          </cylinder>
        </geometry>
        <material>
          <diffuse>0 0 1 1</diffuse>
          <ambient>0 0 1 1</ambient>
        </material>
      </visual>
    </link>
    <joint name='joint1' type='revolute'>
      <pose relative_to='link0'>0 0 0.02 0 0 0</pose>
      <parent>link0</parent>
      <child>link1</child>
      <axis>
        <xyz>0 1 0</xyz>
        <limit>
          <lower>-1.5700000000000001</lower>
          <upper>1.5700000000000001</upper>
          <effort>10</effort>
          <velocity>1</velocity>
        </limit>
        <dynamics>
          <spring_reference>0</spring_reference>
          <spring_stiffness>0</spring_stiffness>
        </dynamics>
      </axis>
    </joint>
    <link name='link1'>
      <pose relative_to='joint1'>0 0 0 0 0 0</pose>
      <inertial>
        <pose>0 0 0 0 0 0</pose>
        <mass>4</mass>
        <inertia>
          <ixx>0.040000000000000001</ixx>
          <ixy>0</ixy>
          <ixz>0</ixz>
          <iyy>0.040000000000000001</iyy>
          <iyz>0</iyz>
          <izz>0.040000000000000001</izz>
        </inertia>
      </inertial>
      <collision name='link1_collision'>
        <pose>0 0 0.13500000000000001 0 0 0</pose>
        <geometry>
          <cylinder>
            <length>0.27000000000000002</length>
            <radius>0.02</radius>
          </cylinder>
        </geometry>
      </collision>
      <visual name='link1_visual'>
        <pose>0 0 0.13500000000000001 0 0 0</pose>
        <geometry>
          <cylinder>
            <length>0.27000000000000002</length>
            <radius>0.02</radius>
          </cylinder>
        </geometry>
        <material>
          <diffuse>0 0 1 1</diffuse>
          <ambient>0 0 1 1</ambient>
        </material>
      </visual>
    </link>
    <joint name='joint2' type='revolute'>
      <pose relative_to='link1'>0 0 0.27000000000000002 0 0 0</pose>
      <parent>link1</parent>
      <child>link2</child>
      <axis>
        <xyz>0 1 0</xyz>
        <limit>
          <lower>-2.5</lower>
          <upper>2.5</upper>
          <effort>10</effort>
          <velocity>1</velocity>
        </limit>
        <dynamics>
          <spring_reference>0</spring_reference>
          <spring_stiffness>0</spring_stiffness>
        </dynamics>
      </axis>
    </joint>
    <link name='link2'>
      <pose relative_to='joint2'>0 0 0 0 0 0</pose>
      <inertial>
        <pose>0 0 0 0 0 0</pose>
        <mass>3.5</mass>
        <inertia>
          <ixx>0.035000000000000003</ixx>
          <ixy>0</ixy>
          <ixz>0</ixz>
          <iyy>0.035000000000000003</iyy>
          <iyz>0</iyz>
          <izz>0.035000000000000003</izz>
        </inertia>
      </inertial>
      <collision name='link2_collision'>
        <pose>0 0 0.13500000000000001 0 0 0</pose>
        <geometry>
          <cylinder>
            <length>0.27000000000000002</length>
            <radius>0.02</radius>
          </cylinder>
        </geometry>
      </collision>
      <visual name='link2_visual'>
        <pose>0 0 0.13500000000000001 0 0 0</pose>
        <geometry>
          <cylinder>
            <length>0.27000000000000002</length>
            <radius>0.02</radius>
          </cylinder>
        </geometry>
        <material>
          <diffuse>0 1 0 1</diffuse>
          <ambient>0 1 0 1</ambient>
        </material>
      </visual>
    </link>
    <joint name='joint3' type='revolute'>
      <pose relative_to='link2'>0 0 0.27000000000000002 0 0 0</pose>
      <parent>link2</parent>
      <child>link3</child>
      <axis>
        <xyz>0 1 0</xyz>
        <limit>
          <lower>-2.5</lower>
          <upper>2.5</upper>
          <effort>10</effort>
          <velocity>1</velocity>
        </limit>
        <dynamics>
          <spring_reference>0</spring_reference>
          <spring_stiffness>0</spring_stiffness>
        </dynamics>
      </axis>
    </joint>
    <link name='link3'>
      <pose relative_to='joint3'>0 0 0 0 0 0</pose>
      <inertial>
        <pose>0 0 0 0 0 0</pose>
        <mass>2.5</mass>
        <inertia>
          <ixx>0.025000000000000001</ixx>
          <ixy>0</ixy>
          <ixz>0</ixz>
          <iyy>0.025000000000000001</iyy>
          <iyz>0</iyz>
          <izz>0.025000000000000001</izz>
        </inertia>
      </inertial>
      <collision name='link3_collision'>
        <pose>0 0 0.17499999999999999 0 0 0</pose>
        <geometry>
          <cylinder>
            <length>0.34999999999999998</length>
            <radius>0.02</radius>
          </cylinder>
        </geometry>
      </collision>
      <visual name='link3_visual'>
        <pose>0 0 0.17499999999999999 0 0 0</pose>
        <geometry>
          <cylinder>
            <length>0.34999999999999998</length>
            <radius>0.02</radius>
          </cylinder>
        </geometry>
        <material>
          <diffuse>1 0 0 1</diffuse>
          <ambient>1 0 0 1</ambient>
        </material>
      </visual>
    </link>
    <joint name='joint4' type='revolute'>
      <pose relative_to='link3'>0 0 0.34999999999999998 0 0 0</pose>
      <parent>link3</parent>
      <child>gripper_base</child>
      <axis>
        <xyz>0 0 1</xyz>
        <limit>
          <lower>-3.1400000000000001</lower>
          <upper>3.1400000000000001</upper>
          <effort>10</effort>
          <velocity>1</velocity>
        </limit>
        <dynamics>
          <spring_reference>0</spring_reference>
          <spring_stiffness>0</spring_stiffness>
        </dynamics>
      </axis>
    </joint>
    <link name='gripper_base'>
      <pose relative_to='joint4'>0 0 0 0 0 0</pose>
      <inertial>
        <pose>0 0 0 0 0 0</pose>
        <mass>1.5</mass>
        <inertia>
          <ixx>0.014999999999999999</ixx>
          <ixy>0</ixy>
          <ixz>0</ixz>
          <iyy>0.014999999999999999</iyy>
          <iyz>0</iyz>
          <izz>0.014999999999999999</izz>
        </inertia>
      </inertial>
      <collision name='gripper_base_collision'>
        <pose>0 0 0.01 0 0 0</pose>
        <geometry>
          <box>
            <size>0.02 0.40000000000000002 0.02</size>
          </box>
        </geometry>
      </collision>
      <visual name='gripper_base_visual'>
        <pose>0 0 0.01 0 0 0</pose>
        <geometry>
          <box>
            <size>0.02 0.40000000000000002 0.02</size>
          </box>
        </geometry>
        <material>
          <diffuse>0.25 0.25 0.25 1</diffuse>
          <ambient>0.25 0.25 0.25 1</ambient>
        </material>
      </visual>
    </link>
    <joint name='finger_left_joint' type='prismatic'>
      <pose relative_to='gripper_base'>0 0.10000000000000001 0.029999999999999999 0 0 0</pose>
      <parent>gripper_base</parent>
      <child>gripper_finger_left</child>
      <axis>
        <xyz>0 1 0</xyz>
        <limit>
          <lower>-0.089999999999999997</lower>
          <upper>0.050000000000000003</upper>
          <effort>10</effort>
          <velocity>0.5</velocity>
        </limit>
        <dynamics>
          <spring_reference>0</spring_reference>
          <spring_stiffness>0</spring_stiffness>
        </dynamics>
      </axis>
    </joint>
    <link name='gripper_finger_left'>
      <pose relative_to='finger_left_joint'>0 0 0 0 0 0</pose>
      <inertial>
        <pose>0 0 0 0 0 0</pose>
        <mass>0.29999999999999999</mass>
        <inertia>
          <ixx>0.0030000000000000001</ixx>
          <ixy>0</ixy>
          <ixz>0</ixz>
          <iyy>0.0030000000000000001</iyy>
          <iyz>0</iyz>
          <izz>0.0030000000000000001</izz>
        </inertia>
      </inertial>
      <collision name='gripper_finger_left_collision'>
        <pose>0 0 0 0 0 0</pose>
        <geometry>
          <box>
            <size>0.01 0.01 0.040000000000000001</size>
          </box>
        </geometry>
      </collision>
      <visual name='gripper_finger_left_visual'>
        <pose>0 0 0 0 0 0</pose>
        <geometry>
          <box>
            <size>0.01 0.01 0.040000000000000001</size>
          </box>
        </geometry>
        <material>
          <diffuse>0 0 1 1</diffuse>
          <ambient>0 0 1 1</ambient>
        </material>
      </visual>
    </link>
    <joint name='finger_right_joint' type='prismatic'>
      <pose relative_to='gripper_base'>0 -0.10000000000000001 0.029999999999999999 0 0 0</pose>
      <parent>gripper_base</parent>
      <child>gripper_finger_right</child>
      <axis>
        <xyz>0 -1 0</xyz>
        <mimic joint='finger_left_joint'>
          <multiplier>1</multiplier>
          <offset>0</offset>
          <reference>0</reference>
        </mimic>
        <limit>
          <lower>-0.089999999999999997</lower>
          <upper>0.050000000000000003</upper>
          <effort>10</effort>
          <velocity>0.5</velocity>
        </limit>
        <dynamics>
          <spring_reference>0</spring_reference>
          <spring_stiffness>0</spring_stiffness>
        </dynamics>
      </axis>
    </joint>
    <link name='gripper_finger_right'>
      <pose relative_to='finger_right_joint'>0 0 0 0 0 0</pose>
      <inertial>
        <pose>0 0 0 0 0 0</pose>
        <mass>0.29999999999999999</mass>
        <inertia>
          <ixx>0.0030000000000000001</ixx>
          <ixy>0</ixy>
          <ixz>0</ixz>
          <iyy>0.0030000000000000001</iyy>
          <iyz>0</iyz>
          <izz>0.0030000000000000001</izz>
        </inertia>
      </inertial>
      <collision name='gripper_finger_right_collision'>
        <pose>0 0 0 0 0 0</pose>
        <geometry>
          <box>
            <size>0.01 0.01 0.040000000000000001</size>
          </box>
        </geometry>
      </collision>
      <visual name='gripper_finger_right_visual'>
        <pose>0 0 0 0 0 0</pose>
        <geometry>
          <box>
            <size>0.01 0.01 0.040000000000000001</size>
          </box>
        </geometry>
        <material>
          <diffuse>0 0 1 1</diffuse>
          <ambient>0 0 1 1</ambient>
        </material>
      </visual>
    </link>
  </model>
</sdf>
