<?xml version="1.0" ?>
<!-- =================================================================================== -->
<!-- |    This document was autogenerated by xacro from rrr_robot.urdf.xacro           | -->
<!-- |    EDITING THIS FILE BY HAND IS NOT RECOMMENDED                                 | -->
<!-- =================================================================================== -->
<robot name="rrr_robot">
  <!--  MATERIALS -->
  <material name="blue">
    <color rgba="0 0 0.8 1"/>
  </material>
  <material name="green">
    <color rgba="0 0.8 0 1"/>
  </material>
  <material name="red">
    <color rgba="0.8 0 0 1"/>
  </material>
  <material name="grey">
    <color rgba="0.2 0.2 0.2 1"/>
  </material>
  <!-- BASE -->
  <link name="base_link">
    <inertial>
      <origin rpy="0 0 0" xyz="0 0 0"/>
      <mass value="5.0"/>
      <inertia ixx="0.05" ixy="0" ixz="0" iyy="0.05" iyz="0" izz="0.05"/>
    </inertial>
    <visual>
      <geometry>
        <cylinder length="0.05" radius="0.01"/>
      </geometry>
      <material name="grey"/>
    </visual>
    <collision>
      <geometry>
        <cylinder length="0.05" radius="0.01"/>
      </geometry>
      <self_collide>true</self_collide>
    </collision>
  </link>
  <joint name="joint0" type="revolute">
    <parent link="base_link"/>
    <child link="link0"/>
    <origin rpy="0 0 0" xyz="0 0 0.05"/>
    <axis xyz="0 0 1"/>
    <limit effort="10.0" lower="-3.14" upper="3.14" velocity="1.0"/>
  </joint>
  <!--  LINK 0 -->
  <link name="link0">
    <inertial>
      <origin rpy="0 0 0" xyz="0 0 0"/>
      <mass value="3.0"/>
      <inertia ixx="0.03" ixy="0" ixz="0" iyy="0.03" iyz="0" izz="0.03"/>
    </inertial>
    <visual>
      <origin rpy="0 0 0" xyz="0 0 0.01"/>
      <geometry>
        <cylinder length="0.02" radius="0.02"/>
      </geometry>
      <material name="blue"/>
    </visual>
    <collision>
      <origin rpy="0 0 0" xyz="0 0 0.01"/>
      <geometry>
        <cylinder length="0.02" radius="0.02"/>
      </geometry>
      <self_collide>true</self_collide>
    </collision>
  </link>
  <joint name="joint1" type="revolute">
    <parent link="link0"/>
    <child link="link1"/>
    <origin rpy="0 0 0" xyz="0 0 0.02"/>
    <axis xyz="0 1 0"/>
    <limit effort="10.0" lower="-1.57" upper="1.57" velocity="1.0"/>
  </joint>
  <!-- LINK 1 -->
  <link name="link1">
    <inertial>
      <origin rpy="0 0 0" xyz="0 0 0"/>
      <mass value="4.0"/>
      <inertia ixx="0.04" ixy="0" ixz="0" iyy="0.04" iyz="0" izz="0.04"/>
    </inertial>
    <visual>
      <origin rpy="0 0 0" xyz="0 0 0.135"/>
      <geometry>
        <cylinder length="0.27" radius="0.02"/>
      </geometry>
      <material name="blue"/>
    </visual>
    <collision>
      <origin rpy="0 0 0" xyz="0 0 0.135"/>
      <geometry>
        <cylinder length="0.27" radius="0.02"/>
      </geometry>
      <self_collide>true</self_collide>
    </collision>
  </link>
  <joint name="joint2" type="revolute">
    <parent link="link1"/>
    <child link="link2"/>
    <origin rpy="0 0 0" xyz="0 0 0.27"/>
    <axis xyz="0 1 0"/>
    <limit effort="10.0" lower="-2.5" upper="2.5" velocity="1.0"/>
  </joint>
  <!--  LINK 2 -->
  <link name="link2">
    <inertial>
      <origin rpy="0 0 0" xyz="0 0 0"/>
      <mass value="3.5"/>
      <inertia ixx="0.035" ixy="0" ixz="0" iyy="0.035" iyz="0" izz="0.035"/>
    </inertial>
    <visual>
      <origin rpy="0 0 0" xyz="0 0 0.135"/>
      <geometry>
        <cylinder length="0.27" radius="0.02"/>
      </geometry>
      <material name="green"/>
    </visual>
    <collision>
      <origin rpy="0 0 0" xyz="0 0 0.135"/>
      <geometry>
        <cylinder length="0.27" radius="0.02"/>
      </geometry>
      <self_collide>true</self_collide>
    </collision>
  </link>
  <joint name="joint3" type="revolute">
    <parent link="link2"/>
    <child link="link3"/>
    <origin rpy="0 0 0" xyz="0 0 0.27"/>
    <axis xyz="0 1 0"/>
    <limit effort="10.0" lower="-2.5" upper="2.5" velocity="1.0"/>
  </joint>
  <!--  LINK 3 -->
  <link name="link3">
    <inertial>
      <origin rpy="0 0 0" xyz="0 0 0"/>
      <mass value="2.5"/>
      <inertia ixx="0.025" ixy="0" ixz="0" iyy="0.025" iyz="0" izz="0.025"/>
    </inertial>
    <visual>
      <origin rpy="0 0 0" xyz="0 0 0.275"/>
      <geometry>
        <cylinder length="0.55" radius="0.02"/>
      </geometry>
      <material name="red"/>
    </visual>
    <collision>
      <origin rpy="0 0 0" xyz="0 0 0.275"/>
      <geometry>
        <cylinder length="0.55" radius="0.02"/>
      </geometry>
      <self_collide>true</self_collide>
    </collision>
  </link>
  <!-- GRIPPER BASE-->
  <joint name="joint4" type="revolute">
    <parent link="link3"/>
    <child link="gripper_base"/>
    <origin rpy="0 0 0" xyz="0 0 0.55"/>
    <axis xyz="0 0 1"/>
    <limit effort="10.0" lower="-3.14" upper="3.14" velocity="1.0"/>
  </joint>
  <link name="gripper_base">
    <inertial>
      <origin rpy="0 0 0" xyz="0 0 0"/>
      <mass value="1.5"/>
      <inertia ixx="0.015" ixy="0" ixz="0" iyy="0.015" iyz="0" izz="0.015"/>
    </inertial>
    <visual>
      <origin rpy="0 0 0" xyz="0 0 0.01"/>
      <geometry>
        <box size="0.02 0.3 0.02"/>
      </geometry>
      <material name="grey"/>
    </visual>
    <collision>
      <origin rpy="0 0 0" xyz="0 0 0.01"/>
      <geometry>
        <box size="0.02 0.3 0.02"/>
      </geometry>
      <self_collide>true</self_collide>
    </collision>
  </link>
  <!--  LEFT FINGER  -->
  <joint name="finger_left_joint" type="prismatic">
    <parent link="gripper_base"/>
    <child link="gripper_finger_left"/>
    <origin rpy="0 0 0" xyz="0 0.10 0.03"/>
    <axis xyz="0 1 0"/>
    <limit effort="10.0" lower="-0.09" upper="0.05" velocity="0.5"/>
  </joint>
  <link name="gripper_finger_left">
    <inertial>
      <origin rpy="0 0 0" xyz="0 0 0"/>
      <mass value="0.3"/>
      <inertia ixx="0.003" ixy="0" ixz="0" iyy="0.003" iyz="0" izz="0.003"/>
    </inertial>
    <visual>
      <geometry>
        <box size="0.01 0.01 0.04"/>
      </geometry>
      <material name="blue"/>
    </visual>
    <collision>
      <geometry>
        <box size="0.01 0.01 0.04"/>
      </geometry>
      <self_collide>true</self_collide>
    </collision>
  </link>
  <!--  RIGHT FINGER -->
  <joint name="finger_right_joint" type="prismatic">
    <parent link="gripper_base"/>
    <child link="gripper_finger_right"/>
    <origin rpy="0 0 0" xyz="0 -0.10 0.03"/>
    <axis xyz="0 -1 0"/>
    <limit effort="10.0" lower="-0.09" upper="0.05" velocity="0.5"/>
    <mimic joint="finger_left_joint" multiplier="1.0" offset="0.0"/>
  </joint>
  <link name="gripper_finger_right">
    <inertial>
      <origin rpy="0 0 0" xyz="0 0 0"/>
      <mass value="0.3"/>
      <inertia ixx="0.003" ixy="0" ixz="0" iyy="0.003" iyz="0" izz="0.003"/>
    </inertial>
    <visual>
      <geometry>
        <box size="0.01 0.01 0.04"/>
      </geometry>
      <material name="blue"/>
    </visual>
    <collision>
      <geometry>
        <box size="0.01 0.01 0.04"/>
      </geometry>
      <self_collide>true</self_collide>
    </collision>
  </link>
</robot>
