<?xml version="1.0"?>
<sdf version="1.8">
  <model name="simple_car">
    <pose>0 0 1.4 0 0 0</pose>
    
    <link name="chassis">
      <inertial>
        <mass>20</mass>
        <inertia>
          <ixx>2.0</ixx><ixy>0</ixy><ixz>0</ixz>
          <iyy>2.0</iyy><iyz>0</iyz>
          <izz>2.0</izz>
        </inertia>
      </inertial>
      <visual name="chassis_visual">
        <geometry>
          <box><size>0.8 0.8 0.8</size></box>
        </geometry>
        <material>
          <ambient>0.2 0.5 0.8 1</ambient>
          <diffuse>0.2 0.5 0.8 1</diffuse>
        </material>
      </visual>
      <collision name="chassis_collision">
        <geometry>
          <box><size>0.8 0.8 0.8</size></box>
        </geometry>
      </collision>
    </link>

    <link name="front_left_wheel">
      <pose>0.3 0.45 -0.4 1.5707 0 0</pose>
      <inertial>
        <mass>1</mass>
        <inertia>
          <ixx>0.02</ixx><ixy>0</ixy><ixz>0</ixz>
          <iyy>0.02</iyy><iyz>0</iyz>
          <izz>0.04</izz>
        </inertia>
      </inertial>
      <visual name="wheel_visual">
        <geometry>
          <cylinder><radius>0.2</radius><length>0.1</length></cylinder>
        </geometry>
        <material>
          <ambient>0.1 0.1 0.1 1</ambient>
          <diffuse>0.1 0.1 0.1 1</diffuse>
        </material>
      </visual>
      <collision name="wheel_collision">
        <geometry>
          <cylinder><radius>0.2</radius><length>0.1</length></cylinder>
        </geometry>
        <surface>
          <friction>
            <ode>
              <mu>100</mu>
              <mu2>100</mu2>
              <slip1>0.0</slip1>
              <slip2>0.0</slip2>
            </ode>
          </friction>
        </surface>
      </collision>
    </link>

    <link name="front_right_wheel">
      <pose>0.3 -0.45 -0.4 1.5707 0 0</pose>
      <inertial>
        <mass>1</mass>
        <inertia>
          <ixx>0.02</ixx><ixy>0</ixy><ixz>0</ixz>
          <iyy>0.02</iyy><iyz>0</iyz>
          <izz>0.04</izz>
        </inertia>
      </inertial>
      <visual name="wheel_visual">
        <geometry>
          <cylinder><radius>0.2</radius><length>0.1</length></cylinder>
        </geometry>
        <material>
          <ambient>0.1 0.1 0.1 1</ambient>
          <diffuse>0.1 0.1 0.1 1</diffuse>
        </material>
      </visual>
      <collision name="wheel_collision">
        <geometry>
          <cylinder><radius>0.2</radius><length>0.1</length></cylinder>
        </geometry>
        <surface>
          <friction>
            <ode>
              <mu>100</mu>
              <mu2>100</mu2>
              <slip1>0.0</slip1>
              <slip2>0.0</slip2>
            </ode>
          </friction>
        </surface>
      </collision>
    </link>

    <link name="rear_left_wheel">
      <pose>-0.3 0.45 -0.4 1.5707 0 0</pose>
      <inertial>
        <mass>1</mass>
        <inertia>
          <ixx>0.02</ixx><ixy>0</ixy><ixz>0</ixz>
          <iyy>0.02</iyy><iyz>0</iyz>
          <izz>0.04</izz>
        </inertia>
      </inertial>
      <visual name="wheel_visual">
        <geometry>
          <cylinder><radius>0.2</radius><length>0.1</length></cylinder>
        </geometry>
        <material>
          <ambient>0.1 0.1 0.1 1</ambient>
          <diffuse>0.1 0.1 0.1 1</diffuse>
        </material>
      </visual>
      <collision name="wheel_collision">
        <geometry>
          <cylinder><radius>0.2</radius><length>0.1</length></cylinder>
        </geometry>
        <surface>
          <friction>
            <ode>
              <mu>100</mu>
              <mu2>100</mu2>
              <slip1>0.0</slip1>
              <slip2>0.0</slip2>
            </ode>
          </friction>
        </surface>
      </collision>
    </link>

    <link name="rear_right_wheel">
      <pose>-0.3 -0.45 -0.4 1.5707 0 0</pose>
      <inertial>
        <mass>1</mass>
        <inertia>
          <ixx>0.02</ixx><ixy>0</ixy><ixz>0</ixz>
          <iyy>0.02</iyy><iyz>0</iyz>
          <izz>0.04</izz>
        </inertia>
      </inertial>
      <visual name="wheel_visual">
        <geometry>
          <cylinder><radius>0.2</radius><length>0.1</length></cylinder>
        </geometry>
        <material>
          <ambient>0.1 0.1 0.1 1</ambient>
          <diffuse>0.1 0.1 0.1 1</diffuse>
        </material>
      </visual>
      <collision name="wheel_collision">
        <geometry>
          <cylinder><radius>0.2</radius><length>0.1</length></cylinder>
        </geometry>
        <surface>
          <friction>
            <ode>
              <mu>100</mu>
              <mu2>100</mu2>
              <slip1>0.0</slip1>
              <slip2>0.0</slip2>
            </ode>
          </friction>
        </surface>
      </collision>
    </link>

    <joint name="front_left_wheel_joint" type="revolute">
      <parent>chassis</parent>
      <child>front_left_wheel</child>
      <axis>
        <xyz>0 0 1</xyz>
        <limit>
          <lower>-1e16</lower>
          <upper>1e16</upper>
        </limit>
      </axis>
    </joint>

    <joint name="front_right_wheel_joint" type="revolute">
      <parent>chassis</parent>
      <child>front_right_wheel</child>
      <axis>
        <xyz>0 0 1</xyz>
        <limit>
          <lower>-1e16</lower>
          <upper>1e16</upper>
        </limit>
      </axis>
    </joint>

    <joint name="rear_left_wheel_joint" type="revolute">
      <parent>chassis</parent>
      <child>rear_left_wheel</child>
      <axis>
        <xyz>0 0 1</xyz>
        <limit>
          <lower>-1e16</lower>
          <upper>1e16</upper>
        </limit>
      </axis>
    </joint>

    <joint name="rear_right_wheel_joint" type="revolute">
      <parent>chassis</parent>
      <child>rear_right_wheel</child>
      <axis>
        <xyz>0 0 1</xyz>
        <limit>
          <lower>-1e16</lower>
          <upper>1e16</upper>
        </limit>
      </axis>
    </joint>

    <plugin filename="ignition-gazebo-diff-drive-system" name="ignition::gazebo::systems::DiffDrive">
      <left_joint>front_left_wheel_joint</left_joint>
      <left_joint>rear_left_wheel_joint</left_joint>
      <right_joint>front_right_wheel_joint</right_joint>
      <right_joint>rear_right_wheel_joint</right_joint>
      <wheel_separation>0.9</wheel_separation>
      <wheel_radius>0.2</wheel_radius>
      <max_linear_acceleration>1</max_linear_acceleration>
      <min_linear_acceleration>-1</min_linear_acceleration>
      <max_angular_acceleration>2</max_angular_acceleration>
      <min_angular_acceleration>-2</min_angular_acceleration>
      <topic>/model/simple_car/cmd_vel</topic>
    </plugin>

    <plugin filename="ignition-gazebo-joint-state-publisher-system" name="ignition::gazebo::systems::JointStatePublisher"/>

  </model>
</sdf>
